Workbook
Name UPDATE: 'Data Sheet'!$E$1

Sheet DCF
A1: NESTLE INDIA LTD — 5-Year Discounted Cash Flow Model
A3: Case Selector (1 = Bear, 2 = Base, 3 = Bull) | B3: 2
A4: Selected Case | B4: =IF($B$3=1,"BEAR",IF($B$3=2,"BASE","BULL")) -> BASE
A6: Market Data
A7: Current Share Price | B7: ='Data Sheet'!B8 -> 1382.65
A8: Diluted Shares Outstanding (cr) | B8: ='Data Sheet'!B6 -> 192.83143
A9: Market Capitalisation | B9: =B7*B8 -> 266618.37
A10: Total Borrowings | B10: ='Historical FS'!K50 -> 444.16
A11: Cash & Bank | B11: ='Historical FS'!K62 -> 1340.87
A12: Net Debt / (Net Cash) | B12: =B10-B11 -> -896.71
A13: FY2026A Revenue | B13: ='Historical FS'!K5 -> 23154.6
A14: FY2026A EBIT | B14: ='Historical FS'!K22 -> 4607.73
A15: FY2026A EBIT Margin (%) | B15: =B14/B13 -> 0.19899847
A17: Bear Case Assumptions
A18: Assumption | B18: FY2027E | C18: FY2028E | D18: FY2029E | E18: FY2030E | F18: FY2031E
A19: Revenue Growth (%) | B19: 0.07 | C19: 0.06 | D19: 0.06 | E19: 0.05 | F19: 0.05
A20: EBIT Margin (%) | B20: 0.185 | C20: 0.183 | D20: 0.18 | E20: 0.18 | F20: 0.18
A21: Tax Rate (%) | B21: 0.255 | C21: 0.255 | D21: 0.255 | E21: 0.255 | F21: 0.255
A22: D&A (% of Revenue) | B22: 0.032 | C22: 0.032 | D22: 0.032 | E22: 0.032 | F22: 0.032
A23: Capex (% of Revenue) | B23: 0.045 | C23: 0.045 | D23: 0.045 | E23: 0.045 | F23: 0.045
A24: Δ NWC (% of Δ Revenue) | B24: -0.03 | C24: -0.03 | D24: -0.03 | E24: -0.03 | F24: -0.03
A26: Base Case Assumptions
A27: Assumption | B27: FY2027E | C27: FY2028E | D27: FY2029E | E27: FY2030E | F27: FY2031E
A28: Revenue Growth (%) | B28: 0.11 | C28: 0.1 | D28: 0.09 | E28: 0.08 | F28: 0.07
A29: EBIT Margin (%) | B29: 0.2 | C29: 0.202 | D29: 0.204 | E29: 0.206 | F29: 0.208
A30: Tax Rate (%) | B30: 0.25 | C30: 0.25 | D30: 0.25 | E30: 0.25 | F30: 0.25
A31: D&A (% of Revenue) | B31: 0.03 | C31: 0.03 | D31: 0.03 | E31: 0.03 | F31: 0.03
A32: Capex (% of Revenue) | B32: 0.036 | C32: 0.036 | D32: 0.036 | E32: 0.036 | F32: 0.036
A33: Δ NWC (% of Δ Revenue) | B33: -0.05 | C33: -0.05 | D33: -0.05 | E33: -0.05 | F33: -0.05
A35: Bull Case Assumptions
A36: Assumption | B36: FY2027E | C36: FY2028E | D36: FY2029E | E36: FY2030E | F36: FY2031E
A37: Revenue Growth (%) | B37: 0.14 | C37: 0.13 | D37: 0.12 | E37: 0.11 | F37: 0.1
A38: EBIT Margin (%) | B38: 0.21 | C38: 0.215 | D38: 0.22 | E38: 0.225 | F38: 0.23
A39: Tax Rate (%) | B39: 0.245 | C39: 0.245 | D39: 0.245 | E39: 0.245 | F39: 0.245
A40: D&A (% of Revenue) | B40: 0.029 | C40: 0.029 | D40: 0.029 | E40: 0.029 | F40: 0.029
A41: Capex (% of Revenue) | B41: 0.034 | C41: 0.034 | D41: 0.034 | E41: 0.034 | F41: 0.034
A42: Δ NWC (% of Δ Revenue) | B42: -0.06 | C42: -0.06 | D42: -0.06 | E42: -0.06 | F42: -0.06
A44: Selected Case
A45: Assumption | B45: FY2027E | C45: FY2028E | D45: FY2029E | E45: FY2030E | F45: FY2031E
A46: Revenue Growth (%) | B46: =CHOOSE($B$3,B19,B28,B37) -> 0.11 | C46: =CHOOSE($B$3,C19,C28,C37) -> 0.1 | D46: =CHOOSE($B$3,D19,D28,D37) -> 0.09 | E46: =CHOOSE($B$3,E19,E28,E37) -> 0.08 | F46: =CHOOSE($B$3,F19,F28,F37) -> 0.07
...

Sheet WACC
A1: Weighted Average Cost of Capital
A3: Cost Of Equity (CAPM)
A4: Risk-Free Rate (10Y India G-Sec) | B4: 0.066
A5: Beta (levered vs Nifty) | B5: 0.6
A6: Equity Risk Premium (India) | B6: 0.07
A7: Cost Of Equity | B7: =B4+B5*B6 -> 0.108
A9: Cost Of Debt
A10: Interest Expense FY2026A | B10: ='Historical FS'!K25 -> 158.31
A11: Average Borrowings | B11: =AVERAGE('Historical FS'!J50:K50) -> 805.505
A12: Implied Interest Cost | B12: =B10/B11 -> 0.19653509
A13: Pre-Tax Cost of Debt (assumed) | B13: 0.075
A14: Tax Rate | B14: =DCF!B48 -> 0.25
A15: After-Tax Cost Of Debt | B15: =B13*(1-B14) -> 0.05625
A17: Capital Structure (Market Values)
A18: Current Share Price | B18: =DCF!B7 -> 1382.65
A19: Diluted Shares Outstanding (cr) | B19: =DCF!B8 -> 192.83143
A20: Market Capitalisation | B20: =B18*B19 -> 266618.37
A21: Total Borrowings | B21: =DCF!B10 -> 444.16
A22: Cash & Bank | B22: =DCF!B11 -> 1340.87
A23: Net Debt / (Net Cash) | B23: =B21-B22 -> -896.71
A24: Total Capitalisation | B24: =B20+B21 -> 267062.53
A26: WACC Calculation
A27: Component | B27: Weight | C27: Cost | D27: Contribution
A28: Equity | B28: =B20/$B$24 -> 0.99833687 | C28: =B7 -> 0.108 | D28: =B28*C28 -> 0.10782038
A29: Debt | B29: =B21/$B$24 -> 0.0016631311 | C29: =B15 -> 0.05625 | D29: =B29*C29 -> 9.3551125e-05
A30: Weighted Average Cost Of Capital | B30: =SUM(D28:D29) -> 0.10791393

Sheet Working Capital
A2: Working Capital
A3: Fiscal Year | B3: FY2018 | C3: FY2019 | D3: FY2020 | E3: FY2021 | F3: FY2022 | G3: FY2026
A4: Sales | B4: ='Profit & Loss'!C4 -> 11292.27 | C4: ='Profit & Loss'!D4 -> 12368.9 | D4: ='Profit & Loss'!E4 -> 13350.03 | E4: ='Profit & Loss'!F4 -> 14740.59 | F4: ='Profit & Loss'!G4 -> 16896.96 | G4: ='Profit & Loss'!K4 -> 23154.6
A5: Δ Sales | B5: ='Profit & Loss'!C4-'Profit & Loss'!B4 -> 1282.67 | C5: ='Profit & Loss'!D4-'Profit & Loss'!C4 -> 1076.63 | D5: ='Profit & Loss'!E4-'Profit & Loss'!D4 -> 981.13 | E5: ='Profit & Loss'!F4-'Profit & Loss'!E4 -> 1390.56 | F5: ='Profit & Loss'!G4-'Profit & Loss'!F4 -> 2156.37 | G5: ='Profit & Loss'!K4-'Profit & Loss'!J4 -> 2953.04
A6: Working capital | B6: ='Balance Sheet'!C16 -> -1455.43 | C6: ='Balance Sheet'!D16 -> -2127.99 | D6: ='Balance Sheet'!E16 -> -2114.93 | E6: ='Balance Sheet'!F16 -> -1802.04 | F6: ='Balance Sheet'!G16 -> -1449.91 | G6: ='Balance Sheet'!K16 -> -1749.6
A7: Δ Working capital | B7: ='Balance Sheet'!C16-'Balance Sheet'!B16 -> -221.95 | C7: ='Balance Sheet'!D16-'Balance Sheet'!C16 -> -672.56 | D7: ='Balance Sheet'!E16-'Balance Sheet'!D16 -> 13.06 | E7: ='Balance Sheet'!F16-'Balance Sheet'!E16 -> 312.89 | F7: ='Balance Sheet'!G16-'Balance Sheet'!F16 -> 352.13 | G7: ='Balance Sheet'!K16-'Balance Sheet'!J16 -> 318.17
A8: Δ NWC ÷ Δ Sales | B8: =B7/B5 -> -0.17303749 | C8: =C7/C5 -> -0.62469 | D8: =D7/D5 -> 0.013311182 | E8: =E7/E5 -> 0.22501007 | F8: =F7/F5 -> 0.16329758 | G8: =G7/G5 -> 0.10774321
A10: Average of the six years | B10: =AVERAGE(B8:G8) -> -0.04806091

Sheet Capex
A2: Capex
A3: Fiscal Year | B3: FY2018 | C3: FY2019 | D3: FY2020 | E3: FY2021 | F3: FY2022 | G3: FY2025 | H3: FY2026
A4: Net block | B4: ='Balance Sheet'!C10 -> 2400.62 | C4: ='Balance Sheet'!D10 -> 2341.45 | D4: ='Balance Sheet'!E10 -> 2179.41 | E4: ='Balance Sheet'!F10 -> 2994.67 | F4: ='Balance Sheet'!G10 -> 3043.7 | G4: ='Balance Sheet'!J10 -> 5473.61 | H4: ='Balance Sheet'!K10 -> 6290.42
A5: Δ Net block | B5: ='Balance Sheet'!C10-'Balance Sheet'!B10 -> -215.56 | C5: ='Balance Sheet'!D10-'Balance Sheet'!C10 -> -59.17 | D5: ='Balance Sheet'!E10-'Balance Sheet'!D10 -> -162.04 | E5: ='Balance Sheet'!F10-'Balance Sheet'!E10 -> 815.26 | F5: ='Balance Sheet'!G10-'Balance Sheet'!F10 -> 49.03 | G5: ='Balance Sheet'!J10-'Balance Sheet'!I10 -> 2013.36 | H5: ='Balance Sheet'!K10-'Balance Sheet'!J10 -> 816.81
A6: Capital work in progress | B6: ='Balance Sheet'!C11 -> 105.2 | C6: ='Balance Sheet'!D11 -> 143.3 | D6: ='Balance Sheet'!E11 -> 638.58 | E6: ='Balance Sheet'!F11 -> 246.23 | F6: ='Balance Sheet'!G11 -> 358.36 | G6: ='Balance Sheet'!J11 -> 1172.56 | H6: ='Balance Sheet'!K11 -> 506.98
A7: Δ CWIP | B7: ='Balance Sheet'!C11-'Balance Sheet'!B11 -> 11.04 | C7: ='Balance Sheet'!D11-'Balance Sheet'!C11 -> 38.1 | D7: ='Balance Sheet'!E11-'Balance Sheet'!D11 -> 495.28 | E7: ='Balance Sheet'!F11-'Balance Sheet'!E11 -> -392.35 | F7: ='Balance Sheet'!G11-'Balance Sheet'!F11 -> 112.13 | G7: ='Balance Sheet'!J11-'Balance Sheet'!I11 -> -569.15 | H7: ='Balance Sheet'!K11-'Balance Sheet'!J11 -> -665.58
A8: Depreciation | B8: ='Profit & Loss'!C8 -> 335.67 | C8: ='Profit & Loss'!D8 -> 370.15 | D8: ='Profit & Loss'!E8 -> 370.38 | E8: ='Profit & Loss'!F8 -> 391.02 | F8: ='Profit & Loss'!G8 -> 403.01 | G8: ='Profit & Loss'!J8 -> 539.92 | H8: ='Profit & Loss'!K8 -> 699.23
A9: Capex | B9: =B5+B7+B8 -> 131.15 | C9: =C5+C7+C8 -> 349.08 | D9: =D5+D7+D8 -> 703.62 | E9: =E5+E7+E8 -> 813.93 | F9: =F5+F7+F8 -> 564.17 | G9: =G5+G7+G8 -> 1984.13 | H9: =H5+H7+H8 -> 850.46
A10: Sales | B10: ='Profit & Loss'!C4 -> 11292.27 | C10: ='Profit & Loss'!D4 -> 12368.9 | D10: ='Profit & Loss'!E4 -> 13350.03 | E10: ='Profit & Loss'!F4 -> 14740.59 | F10: ='Profit & Loss'!G4 -> 16896.96 | G10: ='Profit & Loss'!J4 -> 20201.56 | H10: ='Profit & Loss'!K4 -> 23154.6
A11: Capex ÷ Sales | B11: =B9/B10 -> 0.01161414 | C11: =C9/C10 -> 0.028222396 | D11: =D9/D10 -> 0.0527055 | E11: =E9/E10 -> 0.055216921 | F11: =F9/F10 -> 0.033388846 | G11: =G9/G10 -> 0.098216672 | H11: =H9/H10 -> 0.036729635
A13: Average Of The Seven Years | B13: =AVERAGE(B11:H11) -> 0.045156301
A14: Average Excluding FY2025 | B14: =AVERAGE(B11:F11,H11) -> 0.036312906
A15: Base Case Assumption Used | B15: =DCF!B32 -> 0.036

Sheet Historical FS
B2: ="Historical Financial Statement - "&'Data Sheet'!B1 -> Historical Financial Statement - NESTLE INDIA LTD
B3: Years | C3: ='Data Sheet'!C16 -> 43465 | D3: ='Data Sheet'!D16 -> 43830 | E3: ='Data Sheet'!E16 -> 44196 | F3: ='Data Sheet'!F16 -> 44561 | G3: ='Data Sheet'!G16 -> 44926 | H3: ='Data Sheet'!H16 -> 45291 | I3: ='Data Sheet'!I16 -> 45382 | J3: ='Data Sheet'!J16 -> 45747 | K3: ='Data Sheet'!K16 -> 46112
A4: # | B4: Income Statement
B5: Sales | C5: =IFERROR('Data Sheet'!C17,0) -> 11292.27 | D5: =IFERROR('Data Sheet'!D17,0) -> 12368.9 | E5: =IFERROR('Data Sheet'!E17,0) -> 13350.03 | F5: =IFERROR('Data Sheet'!F17,0) -> 14740.59 | G5: =IFERROR('Data Sheet'!G17,0) -> 16896.96 | H5: =IFERROR('Data Sheet'!H17,0) -> 19126.3 | I5: =IFERROR('Data Sheet'!I17,0) -> 24393.89 | J5: =IFERROR('Data Sheet'!J17,0) -> 20201.56 | K5: =IFERROR('Data Sheet'!K17,0) -> 23154.6
B6: Sales Growth | C6: - | D6: =IFERROR(D5/C5-1,0) -> 0.095342212 | E6: =IFERROR(E5/D5-1,0) -> 0.079322333 | F6: =IFERROR(F5/E5-1,0) -> 0.10416156 | G6: =IFERROR(G5/F5-1,0) -> 0.1462879 | H6: =IFERROR(H5/G5-1,0) -> 0.13193734 | I6: =I5/H5-1 -> 0.27541082 | J6: =J5/I5-1 -> -0.17185984 | K6: =K5/J5-1 -> 0.14617881
B8: COGS | C8: =IFERROR(SUM('Data Sheet'!C18,'Data Sheet'!C20,'Data Sheet'!C21,'Data Sheet'!C22)-1*'Data Sheet'!C19,0) -> 6241.4 | D8: =IFERROR(SUM('Data Sheet'!D18,'Data Sheet'!D20,'Data Sheet'!D21,'Data Sheet'!D22)-1*'Data Sheet'!D19,0) -> 7003.97 | E8: =IFERROR(SUM('Data Sheet'!E18,'Data Sheet'!E20,'Data Sheet'!E21,'Data Sheet'!E22)-1*'Data Sheet'!E19,0) -> 7687.4 | F8: =IFERROR(SUM('Data Sheet'!F18,'Data Sheet'!F20,'Data Sheet'!F21,'Data Sheet'!F22)-1*'Data Sheet'!F19,0) -> 8521.15 | G8: =IFERROR(SUM('Data Sheet'!G18,'Data Sheet'!G20,'Data Sheet'!G21,'Data Sheet'!G22)-1*'Data Sheet'!G19,0) -> 10221.7 | H8: =IFERROR(SUM('Data Sheet'!H18,'Data Sheet'!H20,'Data Sheet'!H21,'Data Sheet'!H22)-1*'Data Sheet'!H19,0) -> 10281.89 | I8: =IFERROR(SUM('Data Sheet'!I18,'Data Sheet'!I20,'Data Sheet'!I21,'Data Sheet'!I22)-1*'Data Sheet'!I19,0) -> 14101.72 | J8: =IFERROR(SUM('Data Sheet'!J18,'Data Sheet'!J20,'Data Sheet'!J21,'Data Sheet'!J22)-1*'Data Sheet'!J19,0) -> 11692.86 | K8: =IFERROR(SUM('Data Sheet'!K18,'Data Sheet'!K20,'Data Sheet'!K21,'Data Sheet'!K22)-1*'Data Sheet'!K19,0) -> 13627.64
B9: Gross Margins | C9: =C8/C5 -> 0.55271438 | D9: =D8/D5 -> 0.5662565 | E9: =E8/E5 -> 0.57583391 | F9: =F8/F5 -> 0.57807388 | G9: =G8/G5 -> 0.60494314 | H9: =H8/H5 -> 0.53757862 | I9: =I8/I5 -> 0.5780841 | J9: =J8/J5 -> 0.57880976 | K9: =K8/K5 -> 0.58855001
B11: Gross Profit | C11: =C5-C8 -> 5050.87 | D11: =D5-D8 -> 5364.93 | E11: =E5-E8 -> 5662.63 | F11: =F5-F8 -> 6219.44 | G11: =G5-G8 -> 6675.26 | H11: =H5-H8 -> 8844.41 | I11: =I5-I8 -> 10292.17 | J11: =J5-J8 -> 8508.7 | K11: =K5-K8 -> 9526.96
B13: Selling & General Expenses | C13: =IFERROR(SUM('Data Sheet'!C23:C24),0) -> 2433.22 | D13: =IFERROR(SUM('Data Sheet'!D23:D24),0) -> 2439.05 | E13: =IFERROR(SUM('Data Sheet'!E23:E24),0) -> 2461.13 | F13: =IFERROR(SUM('Data Sheet'!F23:F24),0) -> 2657.04 | G13: =IFERROR(SUM('Data Sheet'!G23:G24),0) -> 2968.97 | H13: =IFERROR(SUM('Data Sheet'!H23:H24),0) -> 4373.42 | I13: =IFERROR(SUM('Data Sheet'!I23:I24),0) -> 4449.05 | J13: =IFERROR(SUM('Data Sheet'!J23:J24),0) -> 3737.37 | K13: =IFERROR(SUM('Data Sheet'!K23:K24),0) -> 4220
B14: S&G Exp % Sales | C14: =C13/C5 -> 0.2154766 | D14: =D13/D5 -> 0.19719215 | E14: =E13/E5 -> 0.18435389 | F14: =F13/F5 -> 0.1802533 | G14: =G13/G5 -> 0.17571031 | H14: =H13/H5 -> 0.22866001 | I14: =I13/I5 -> 0.18238379 | J14: =J13/J5 -> 0.18500403 | K14: =K13/K5 -> 0.1822532
B16: EBITDA | C16: =C11-C13 -> 2617.65 | D16: =D11-D13 -> 2925.88 | E16: =E11-E13 -> 3201.5 | F16: =F11-F13 -> 3562.4 | G16: =G11-G13 -> 3706.29 | H16: =H11-H13 -> 4470.99 | I16: =I11-I13 -> 5843.12 | J16: =J11-J13 -> 4771.33 | K16: =K11-K13 -> 5306.96
B17: EBITDA % Sales | C17: =C16/C5 -> 0.23180902 | D17: =D16/D5 -> 0.23655135 | E17: =E16/E5 -> 0.2398122 | F17: =F16/F5 -> 0.24167282 | G17: =G16/G5 -> 0.21934656 | H17: =H16/H5 -> 0.23376137 | I17: =I16/I5 -> 0.23953211 | J17: =J16/J5 -> 0.23618622 | K17: =K16/K5 -> 0.22919679
B19: Depreciation | C19: =IFERROR('Data Sheet'!C26,0) -> 335.67 | D19: =IFERROR('Data Sheet'!D26,0) -> 370.15 | E19: =IFERROR('Data Sheet'!E26,0) -> 370.38 | F19: =IFERROR('Data Sheet'!F26,0) -> 391.02 | G19: =IFERROR('Data Sheet'!G26,0) -> 403.01 | H19: =IFERROR('Data Sheet'!H26,0) -> 428.91 | I19: =IFERROR('Data Sheet'!I26,0) -> 567.75 | J19: =IFERROR('Data Sheet'!J26,0) -> 539.92 | K19: =IFERROR('Data Sheet'!K26,0) -> 699.23
B20: Depreciation % Sales | C20: =C19/C5 -> 0.029725644 | D20: =D19/D5 -> 0.029925862 | E20: =E19/E5 -> 0.027743758 | F20: =F19/F5 -> 0.026526754 | G20: =G19/G5 -> 0.023851036 | H20: =H19/H5 -> 0.022425142 | I20: =I19/I5 -> 0.023274271 | J20: =J19/J5 -> 0.026726649 | K20: =K19/K5 -> 0.030198319
B22: EBIT | C22: =C16-C19 -> 2281.98 | D22: =D16-D19 -> 2555.73 | E22: =E16-E19 -> 2831.12 | F22: =F16-F19 -> 3171.38 | G22: =G16-G19 -> 3303.28 | H22: =H16-H19 -> 4042.08 | I22: =I16-I19 -> 5275.37 | J22: =J16-J19 -> 4231.41 | K22: =K16-K19 -> 4607.73
B23: EBIT % Sales | C23: =C22/C5 -> 0.20208337 | D23: =D22/D5 -> 0.20662549 | E23: =E22/E5 -> 0.21206844 | F23: =F22/F5 -> 0.21514607 | G23: =G22/G5 -> 0.19549552 | H23: =H22/H5 -> 0.21133622 | I23: =I22/I5 -> 0.21625784 | J23: =J22/J5 -> 0.20945957 | K23: =K22/K5 -> 0.19899847
B25: Interest | C25: =IFERROR('Data Sheet'!C27,0) -> 111.95 | D25: =IFERROR('Data Sheet'!D27,0) -> 129.12 | E25: =IFERROR('Data Sheet'!E27,0) -> 164.18 | F25: =IFERROR('Data Sheet'!F27,0) -> 201.68 | G25: =IFERROR('Data Sheet'!G27,0) -> 154.57 | H25: =IFERROR('Data Sheet'!H27,0) -> 119.29 | I25: =IFERROR('Data Sheet'!I27,0) -> 145.49 | J25: =IFERROR('Data Sheet'!J27,0) -> 136 | K25: =IFERROR('Data Sheet'!K27,0) -> 158.31
B26: Interest % Sales | C26: =C25/C5 -> 0.0099138614 | D26: =D25/D5 -> 0.010439085 | E26: =E25/E5 -> 0.0122981 | F26: =F25/F5 -> 0.013681949 | G26: =G25/G5 -> 0.0091477994 | H26: =H25/H5 -> 0.0062369617 | I26: =I25/I5 -> 0.0059641984 | J26: =J25/J5 -> 0.0067321534 | K26: =K25/K5 -> 0.0068370864
B28: EBT | C28: =C16-C25-C19 -> 2170.03 | D28: =D16-D25-D19 -> 2426.61 | E28: =E16-E25-E19 -> 2666.94 | F28: =F16-F25-F19 -> 2969.7 | G28: =G16-G25-G19 -> 3148.71 | H28: =H16-H25-H19 -> 3922.79 | I28: =I16-I25-I19 -> 5129.88 | J28: =J16-J25-J19 -> 4095.41 | K28: =K16-K25-K19 -> 4449.42
B29: EBT % Sales | C29: =C28/C5 -> 0.19216951 | D29: =D28/D5 -> 0.1961864 | E29: =E28/E5 -> 0.19977034 | F29: =F28/F5 -> 0.20146412 | G29: =G28/G5 -> 0.18634772 | H29: =H28/H5 -> 0.20509926 | I29: =I28/I5 -> 0.21029364 | J29: =J28/J5 -> 0.20272741 | K29: =K28/K5 -> 0.19216138
B31: Tax | C31: =IFERROR('Data Sheet'!C29,0) -> 822.02 | D31: =IFERROR('Data Sheet'!D29,0) -> 705.05 | E31: =IFERROR('Data Sheet'!E29,0) -> 730.36 | F31: =IFERROR('Data Sheet'!F29,0) -> 738.91 | G31: =IFERROR('Data Sheet'!G29,0) -> 865.45 | H31: =IFERROR('Data Sheet'!H29,0) -> 1039.62 | I31: =IFERROR('Data Sheet'!I29,0) -> 1356.03 | J31: =IFERROR('Data Sheet'!J29,0) -> 1132.97 | K31: =IFERROR('Data Sheet'!K29,0) -> 1065.05
B32: Effective Tax Rate | C32: =C31/C28 -> 0.37880582 | D32: =D31/D28 -> 0.29054937 | E32: =E31/E28 -> 0.27385693 | F32: =F31/F28 -> 0.24881638 | G32: =G31/G28 -> 0.27485859 | H32: =H31/H28 -> 0.26502056 | I32: =I31/I28 -> 0.26433952 | J32: =J31/J28 -> 0.27664385 | K32: =K31/K28 -> 0.23936828
B34: Net Profit | C34: =C28-C31 -> 1348.01 | D34: =D28-D31 -> 1721.56 | E34: =E28-E31 -> 1936.58 | F34: =F28-F31 -> 2230.79 | G34: =G28-G31 -> 2283.26 | H34: =H28-H31 -> 2883.17 | I34: =I28-I31 -> 3773.85 | J34: =J28-J31 -> 2962.44 | K34: =K28-K31 -> 3384.37
B35: Net Margins | C35: =C34/C5 -> 0.11937458 | D35: =D34/D5 -> 0.13918457 | E35: =E34/E5 -> 0.14506185 | F35: =F34/F5 -> 0.15133655 | G35: =G34/G5 -> 0.13512845 | H35: =H34/H5 -> 0.15074374 | I35: =I34/I5 -> 0.15470472 | J35: =J34/J5 -> 0.14664412 | K35: =K34/K5 -> 0.14616405
B37: No. of Equity Shares | C37: =IFERROR('Data Sheet'!C93,0) -> 192.8 | D37: =IFERROR('Data Sheet'!D93,0) -> 192.8 | E37: =IFERROR('Data Sheet'!E93,0) -> 192.8 | F37: =IFERROR('Data Sheet'!F93,0) -> 192.8 | G37: =IFERROR('Data Sheet'!G93,0) -> 192.8 | H37: =IFERROR('Data Sheet'!H93,0) -> 192.8 | I37: =IFERROR('Data Sheet'!I93,0) -> 192.83 | J37: =IFERROR('Data Sheet'!J93,0) -> 192.83 | K37: =IFERROR('Data Sheet'!K93,0) -> 192.83
B39: EPS | C39: =IFERROR(C34/C37,0) -> 6.9917531 | D39: =IFERROR(D34/D37,0) -> 8.9292531 | E39: =IFERROR(E34/E37,0) -> 10.044502 | F39: =IFERROR(F34/F37,0) -> 11.570488 | G39: =IFERROR(G34/G37,0) -> 11.842635 | H39: =IFERROR(H34/H37,0) -> 14.954201 | I39: =IFERROR(I34/I37,0) -> 19.570866 | J39: =IFERROR(J34/J37,0) -> 15.362962 | K39: =IFERROR(K34/K37,0) -> 17.551055
B40: EPS Growth | C40: - | D40: =IFERROR(D42/C42,0) -> 2.9739094 | E40: =IFERROR(E42/D42,0) -> 0.58479603 | F40: =IFERROR(F42/E42,0) -> 1 | G40: =IFERROR(G42/F42,0) -> 1.1 | H40: =IFERROR(H42/G42,0) -> 0.79091003 | I40: =I42/H42 -> 1.8502822 | J40: =J42/I42 -> 0.8385104 | K40: =K42/J42 -> 0.88884279
B42: Dividend per Share | C42: =IFERROR('Data Sheet'!C31/'Historical FS'!C37,0) -> 5.7511929 | D42: =IFERROR('Data Sheet'!D31/'Historical FS'!D37,0) -> 17.103527 | E42: =IFERROR('Data Sheet'!E31/'Historical FS'!E37,0) -> 10.002075 | F42: =IFERROR('Data Sheet'!F31/'Historical FS'!F37,0) -> 10.002075 | G42: =IFERROR('Data Sheet'!G31/'Historical FS'!G37,0) -> 11.002282 | H42: =IFERROR('Data Sheet'!H31/'Historical FS'!H37,0) -> 8.7018154 | I42: =IFERROR('Data Sheet'!I31/'Historical FS'!I37,0) -> 16.100814 | J42: =IFERROR('Data Sheet'!J31/'Historical FS'!J37,0) -> 13.5007 | K42: =IFERROR('Data Sheet'!K31/'Historical FS'!K37,0) -> 12
B43: Dividend Payout Ratio | C43: =IFERROR(C42/C39,0) -> 0.82256808 | D43: =IFERROR(D42/D39,0) -> 1.9154488 | E43: =IFERROR(E42/E39,0) -> 0.99577606 | F43: =IFERROR(F42/F39,0) -> 0.86444712 | G43: =IFERROR(G42/G39,0) -> 0.92904006 | H43: =IFERROR(H42/H39,0) -> 0.5818977 | I43: =IFERROR(I42/I39,0) -> 0.82269301 | J43: =IFERROR(J42/J39,0) -> 0.87878236 | K43: =IFERROR(K42/K39,0) -> 0.68371957
B45: Retained Earnings | C45: =IFERROR(IF(C39>C42,1-C43,0),0) -> 0.17743192 | D45: =IFERROR(IF(D39>D42,1-D43,0),0) -> 0 | E45: =IFERROR(IF(E39>E42,1-E43,0),0) -> 0.0042239412 | F45: =IFERROR(IF(F39>F42,1-F43,0),0) -> 0.13555288 | G45: =IFERROR(IF(G39>G42,1-G43,0),0) -> 0.070959943 | H45: =IFERROR(IF(H39>H42,1-H43,0),0) -> 0.4181023 | I45: =IFERROR(IF(I39>I42,1-I43,0),0) -> 0.17730699 | J45: =IFERROR(IF(J39>J42,1-J43,0),0) -> 0.12121764 | K45: =IFERROR(IF(K39>K42,1-K43,0),0) -> 0.31628043
A47: # | B47: Balance Sheet
B48: Equity Share Capital | C48: =IFERROR('Data Sheet'!C57,0) -> 96.42 | D48: =IFERROR('Data Sheet'!D57,0) -> 96.42 | E48: =IFERROR('Data Sheet'!E57,0) -> 96.42 | F48: =IFERROR('Data Sheet'!F57,0) -> 96.42 | G48: =IFERROR('Data Sheet'!G57,0) -> 96.42 | H48: =IFERROR('Data Sheet'!H57,0) -> 96.42 | I48: =IFERROR('Data Sheet'!I57,0) -> 96.42 | J48: =IFERROR('Data Sheet'!J57,0) -> 96.42 | K48: =IFERROR('Data Sheet'!K57,0) -> 192.83
B49: Reserves | C49: =IFERROR('Data Sheet'!C58,0) -> 3577.32 | D49: =IFERROR('Data Sheet'!D58,0) -> 1822.45 | E49: =IFERROR('Data Sheet'!E58,0) -> 1922.92 | F49: =IFERROR('Data Sheet'!F58,0) -> 1849.96 | G49: =IFERROR('Data Sheet'!G58,0) -> 2362.75 | H49: =IFERROR('Data Sheet'!H58,0) -> 2362.75 | I49: =IFERROR('Data Sheet'!I58,0) -> 3244.47 | J49: =IFERROR('Data Sheet'!J58,0) -> 4020.73 | K49: =IFERROR('Data Sheet'!K58,0) -> 5116.41
B50: Borrowings | C50: =IFERROR('Data Sheet'!C59,0) -> 35.14 | D50: =IFERROR('Data Sheet'!D59,0) -> 188.94 | E50: =IFERROR('Data Sheet'!E59,0) -> 147.49 | F50: =IFERROR('Data Sheet'!F59,0) -> 266.46 | G50: =IFERROR('Data Sheet'!G59,0) -> 270.52 | H50: =IFERROR('Data Sheet'!H59,0) -> 270.52 | I50: =IFERROR('Data Sheet'!I59,0) -> 344.53 | J50: =IFERROR('Data Sheet'!J59,0) -> 1166.85 | K50: =IFERROR('Data Sheet'!K59,0) -> 444.16
B51: Other Liabilities | C51: =IFERROR('Data Sheet'!C60,0) -> 4379.2 | D51: =IFERROR('Data Sheet'!D60,0) -> 5065.13 | E51: =IFERROR('Data Sheet'!E60,0) -> 5732.9 | F51: =IFERROR('Data Sheet'!F60,0) -> 6021.29 | G51: =IFERROR('Data Sheet'!G60,0) -> 6249.05 | H51: =IFERROR('Data Sheet'!H60,0) -> 6249.05 | I51: =IFERROR('Data Sheet'!I60,0) -> 6837.64 | J51: =IFERROR('Data Sheet'!J60,0) -> 7039.89 | K51: =IFERROR('Data Sheet'!K60,0) -> 7603.77
B52: Total Liabilities | C52: =IFERROR('Data Sheet'!C61,0) -> 8088.08 | D52: =IFERROR('Data Sheet'!D61,0) -> 7172.94 | E52: =IFERROR('Data Sheet'!E61,0) -> 7899.73 | F52: =IFERROR('Data Sheet'!F61,0) -> 8234.13 | G52: =IFERROR('Data Sheet'!G61,0) -> 8978.74 | H52: =IFERROR('Data Sheet'!H61,0) -> 8978.74 | I52: =IFERROR('Data Sheet'!I61,0) -> 10523.06 | J52: =IFERROR('Data Sheet'!J61,0) -> 12323.89 | K52: =IFERROR('Data Sheet'!K61,0) -> 13357.17
B54: Fixed Assets Net Block | C54: =IFERROR('Data Sheet'!C62,0) -> 2400.62 | D54: =IFERROR('Data Sheet'!D62,0) -> 2341.45 | E54: =IFERROR('Data Sheet'!E62,0) -> 2179.41 | F54: =IFERROR('Data Sheet'!F62,0) -> 2994.67 | G54: =IFERROR('Data Sheet'!G62,0) -> 3043.7 | H54: =IFERROR('Data Sheet'!H62,0) -> 3043.7 | I54: =IFERROR('Data Sheet'!I62,0) -> 3460.25 | J54: =IFERROR('Data Sheet'!J62,0) -> 5473.61 | K54: =IFERROR('Data Sheet'!K62,0) -> 6290.42
B55: Capital Work in Progress | C55: =IFERROR('Data Sheet'!C63,0) -> 105.2 | D55: =IFERROR('Data Sheet'!D63,0) -> 143.3 | E55: =IFERROR('Data Sheet'!E63,0) -> 638.58 | F55: =IFERROR('Data Sheet'!F63,0) -> 246.23 | G55: =IFERROR('Data Sheet'!G63,0) -> 358.36 | H55: =IFERROR('Data Sheet'!H63,0) -> 358.36 | I55: =IFERROR('Data Sheet'!I63,0) -> 1741.71 | J55: =IFERROR('Data Sheet'!J63,0) -> 1172.56 | K55: =IFERROR('Data Sheet'!K63,0) -> 506.98
B56: Investments | C56: =IFERROR('Data Sheet'!C64,0) -> 2658.49 | D56: =IFERROR('Data Sheet'!D64,0) -> 1751.05 | E56: =IFERROR('Data Sheet'!E64,0) -> 1463.77 | F56: =IFERROR('Data Sheet'!F64,0) -> 773.98 | G56: =IFERROR('Data Sheet'!G64,0) -> 777.54 | H56: =IFERROR('Data Sheet'!H64,0) -> 777.54 | I56: =IFERROR('Data Sheet'!I64,0) -> 463.87 | J56: =IFERROR('Data Sheet'!J64,0) -> 705.6 | K56: =IFERROR('Data Sheet'!K64,0) -> 705.6
B57: Other Assets | C57: =IFERROR('Data Sheet'!C65-SUM('Data Sheet'!C67:C69),0) -> 223.57 | D57: =IFERROR('Data Sheet'!D65-SUM('Data Sheet'!D67:D69),0) -> 221.69 | E57: =IFERROR('Data Sheet'!E65-SUM('Data Sheet'!E67:E69),0) -> 266.69 | F57: =IFERROR('Data Sheet'!F65-SUM('Data Sheet'!F67:F69),0) -> 1725.22 | G57: =IFERROR('Data Sheet'!G65-SUM('Data Sheet'!G67:G69),0) -> 1732.93 | H57: =IFERROR('Data Sheet'!H65-SUM('Data Sheet'!H67:H69),0) -> 1732.93 | I57: =IFERROR('Data Sheet'!I65-SUM('Data Sheet'!I67:I69),0) -> 1688.56 | J57: =IFERROR('Data Sheet'!J65-SUM('Data Sheet'!J67:J69),0) -> 1663.18 | K57: =IFERROR('Data Sheet'!K65-SUM('Data Sheet'!K67:K69),0) -> 1614.61
...

Sheet Data Sheet
A1: COMPANY NAME | B1: NESTLE INDIA LTD | E1: =IF(B2<>B3, "A NEW VERSION OF THE WORKSHEET IS AVAILABLE", "")
A2: LATEST VERSION | B2: 2.1 | E2: PLEASE DO NOT MAKE ANY CHANGES TO THIS SHEET
A3: CURRENT VERSION | B3: 2.1
A5: META
A6: Number of shares | B6: =IF(B9>0, B9/B8, 0) -> 192.83143
A7: Face Value | B7: 1
A8: Current Price | B8: 1382.65
A9: Market Capitalization | B9: 266618.37
A15: PROFIT & LOSS
A16: Report Date | B16: 43100 | C16: 43465 | D16: 43830 | E16: 44196 | F16: 44561 | G16: 44926 | H16: 45291 | I16: 45382 | J16: 45747 | K16: 46112
A17: Sales | B17: 10009.6 | C17: 11292.27 | D17: 12368.9 | E17: 13350.03 | F17: 14740.59 | G17: 16896.96 | H17: 19126.3 | I17: 24393.89 | J17: 20201.56 | K17: 23154.6
A18: Raw Material Cost | B18: 3696.99 | C18: 3829.22 | D18: 4520.91 | E18: 4901.74 | F18: 5301.26 | G18: 6660.42 | H18: 8472.72 | I18: 9201.11 | J18: 7646.63 | K18: 9113.96
A19: Change in Inventory | B19: 79.56 | C19: 6.01 | D19: 144.19 | E19: 69.33 | F19: 67.59 | G19: 250.27 | H19: 40.01 | I19: 45.68 | J19: 139.66 | K19: 168.23
A20: Power and Fuel | B20: 288.44 | C20: 344.18 | D20: 340.53 | E20: 313.68 | F20: 408.06 | G20: 572.61 | I20: 674.83 | J20: 541.42 | K20: 587.21
A21: Other Mfr. Exp | B21: 897.84 | C21: 949.86 | D21: 1028.55 | E21: 1040.36 | F21: 1349.48 | G21: 1603.48 | I21: 1935.4 | J21: 1582.45 | K21: 1816.29
A22: Employee Cost | B22: 1017.45 | C22: 1124.15 | D22: 1258.17 | E22: 1500.95 | F22: 1529.94 | G22: 1635.46 | H22: 1849.18 | I22: 2336.06 | J22: 2062.02 | K22: 2278.41
A23: Selling and admin | B23: 1823.98 | C23: 2145.82 | D23: 2226.13 | E23: 2246.9 | F23: 2902.12 | G23: 3192.15 | I23: 4837.58 | J23: 4126.54 | K23: 4780.9
A24: Other Expenses | B24: 267.93 | C24: 287.4 | D24: 212.92 | E24: 214.23 | F24: -245.08 | G24: -223.18 | H24: 4373.42 | I24: -388.53 | J24: -389.17 | K24: -560.9
A25: Other Income | B25: 176.92 | C25: 258.92 | D25: 246.88 | E25: 145.85 | F25: -112.38 | G25: 107.26 | H25: 115.5 | I25: 158.99 | J25: 352.06 | K25: 160.23
A26: Depreciation | B26: 342.25 | C26: 335.67 | D26: 370.15 | E26: 370.38 | F26: 391.02 | G26: 403.01 | H26: 428.91 | I26: 567.75 | J26: 539.92 | K26: 699.23
A27: Interest | B27: 91.9 | C27: 111.95 | D27: 129.12 | E27: 164.18 | F27: 201.68 | G27: 154.57 | H27: 119.29 | I27: 145.49 | J27: 136 | K27: 158.31
A28: Profit before tax | B28: 1839.3 | C28: 2428.95 | D28: 2673.49 | E28: 2812.79 | F28: 2857.32 | G28: 3255.97 | H28: 4038.29 | I28: 5288.87 | J28: 4447.47 | K28: 4609.65
A29: Tax | B29: 614.11 | C29: 822.02 | D29: 705.05 | E29: 730.36 | F29: 738.91 | G29: 865.45 | H29: 1039.62 | I29: 1356.03 | J29: 1132.97 | K29: 1065.05
A30: Net profit | B30: 1225.19 | C30: 1606.93 | D30: 1968.44 | E30: 2082.43 | F30: 2118.41 | G30: 2390.52 | H30: 2998.67 | I30: 3932.84 | J30: 3314.5 | K30: 3544.6
A31: Dividend Amount | B31: 829.21 | C31: 1108.83 | D31: 3297.56 | E31: 1928.4 | F31: 1928.4 | G31: 2121.24 | H31: 1677.71 | I31: 3104.72 | J31: 2603.34 | K31: 2313.96
A40: Quarters
A41: Report Date | B41: 45382 | C41: 45473 | D41: 45565 | E41: 45657 | F41: 45747 | G41: 45838 | H41: 45930 | I41: 46022 | J41: 46112 | K41: 46203
A42: Sales | B42: 5267.59 | C42: 4813.95 | D42: 5104 | E42: 4779.73 | F42: 5503.88 | G42: 5096.16 | H42: 5643.61 | I42: 5667.04 | J42: 6747.79 | K42: 6378.18
A43: Expenses | B43: 3917.54 | C43: 3699.62 | D43: 3936.27 | E43: 3677.04 | F43: 4115.58 | G43: 3996.03 | H43: 4406.97 | I43: 4466.09 | J43: 4976.19 | K43: 4840.05
A44: Other Income | B44: 36.83 | C44: 39.12 | D44: 297.68 | E44: 4.44 | F44: 9.1 | G44: 4.17 | H44: 1.64 | I44: 169.78 | J44: -17.72 | K44: 16.24
A45: Depreciation | B45: 110.1 | C45: 112.71 | D45: 121.6 | E45: 150.27 | F45: 155.34 | G45: 156.94 | H45: 163.35 | I45: 174.41 | J45: 204.53 | K45: 187.8
A46: Interest | B46: 26.2 | C46: 31.68 | D46: 32.22 | E46: 34.6 | F46: 37.5 | G46: 46.89 | H46: 46.41 | I46: 28.25 | J46: 36.76 | K46: 42.18
A47: Profit before tax | B47: 1250.58 | C47: 1009.06 | D47: 1311.59 | E47: 922.26 | F47: 1204.56 | G47: 900.47 | H47: 1028.52 | I47: 1168.07 | J47: 1512.59 | K47: 1324.39
A48: Tax | B48: 316.41 | C48: 262.46 | D48: 325.23 | E48: 226.13 | F48: 319.15 | G48: 241.24 | H48: 275.32 | I48: 150.01 | J48: 398.48 | K48: 349.27
A49: Net profit | B49: 934.17 | C49: 746.6 | D49: 986.36 | E49: 696.13 | F49: 885.41 | G49: 659.23 | H49: 753.2 | I49: 1018.06 | J49: 1114.11 | K49: 975.12
A50: Operating Profit | B50: 1350.05 | C50: 1114.33 | D50: 1167.73 | E50: 1102.69 | F50: 1388.3 | G50: 1100.13 | H50: 1236.64 | I50: 1200.95 | J50: 1771.6 | K50: 1538.13
A55: BALANCE SHEET
A56: Report Date | B56: 43100 | C56: 43465 | D56: 43830 | E56: 44196 | F56: 44561 | G56: 44926 | H56: 45291 | I56: 45382 | J56: 45747 | K56: 46112
A57: Equity Share Capital | B57: 96.42 | C57: 96.42 | D57: 96.42 | E57: 96.42 | F57: 96.42 | G57: 96.42 | H57: 96.42 | I57: 96.42 | J57: 96.42 | K57: 192.83
A58: Reserves | B58: 3324.17 | C58: 3577.32 | D58: 1822.45 | E58: 1922.92 | F58: 1849.96 | G58: 2362.75 | H58: 2362.75 | I58: 3244.47 | J58: 4020.73 | K58: 5116.41
...

Sheet Profit & Loss
A1: ='Data Sheet'!B1 -> NESTLE INDIA LTD | H1: =UPDATE
A3: Narration | B3: ='Data Sheet'!B16 -> 43100 | C3: ='Data Sheet'!C16 -> 43465 | D3: ='Data Sheet'!D16 -> 43830 | E3: ='Data Sheet'!E16 -> 44196 | F3: ='Data Sheet'!F16 -> 44561 | G3: ='Data Sheet'!G16 -> 44926 | H3: ='Data Sheet'!H16 -> 45291 | I3: ='Data Sheet'!I16 -> 45382 | ... K3: ='Data Sheet'!K16 -> 46112
A4: Sales | B4: ='Data Sheet'!B17 -> 10009.6 | C4: ='Data Sheet'!C17 -> 11292.27 | D4: ='Data Sheet'!D17 -> 12368.9 | E4: ='Data Sheet'!E17 -> 13350.03 | F4: ='Data Sheet'!F17 -> 14740.59 | G4: ='Data Sheet'!G17 -> 16896.96 | H4: ='Data Sheet'!H17 -> 19126.3 | I4: ='Data Sheet'!I17 -> 24393.89 | ... K4: ='Data Sheet'!K17 -> 23154.6
A5: Expenses | B5: =SUM('Data Sheet'!B18,'Data Sheet'!B20:B24, -1*'Data Sheet'!B19) -> 7913.07 | C5: =SUM('Data Sheet'!C18,'Data Sheet'!C20:C24, -1*'Data Sheet'!C19) -> 8674.62 | D5: =SUM('Data Sheet'!D18,'Data Sheet'!D20:D24, -1*'Data Sheet'!D19) -> 9443.02 | E5: =SUM('Data Sheet'!E18,'Data Sheet'!E20:E24, -1*'Data Sheet'!E19) -> 10148.53 | F5: =SUM('Data Sheet'!F18,'Data Sheet'!F20:F24, -1*'Data Sheet'!F19) -> 11178.19 | G5: =SUM('Data Sheet'!G18,'Data Sheet'!G20:G24, -1*'Data Sheet'!G19) -> 13190.67 | H5: =SUM('Data Sheet'!H18,'Data Sheet'!H20:H24, -1*'Data Sheet'!H19) -> 14655.31 | I5: =SUM('Data Sheet'!I18,'Data Sheet'!I20:I24, -1*'Data Sheet'!I19) -> 18550.77 | ... K5: =SUM('Data Sheet'!K18,'Data Sheet'!K20:K24, -1*'Data Sheet'!K19) -> 17847.64
A6: Operating Profit | B6: =B4-B5 -> 2096.53 | C6: =C4-C5 -> 2617.65 | D6: =D4-D5 -> 2925.88 | E6: =E4-E5 -> 3201.5 | F6: =F4-F5 -> 3562.4 | G6: =G4-G5 -> 3706.29 | H6: =H4-H5 -> 4470.99 | I6: =I4-I5 -> 5843.12 | ... K6: =K4-K5 -> 5306.96
A7: Other Income | B7: ='Data Sheet'!B25 -> 176.92 | C7: ='Data Sheet'!C25 -> 258.92 | D7: ='Data Sheet'!D25 -> 246.88 | E7: ='Data Sheet'!E25 -> 145.85 | F7: ='Data Sheet'!F25 -> -112.38 | G7: ='Data Sheet'!G25 -> 107.26 | H7: ='Data Sheet'!H25 -> 115.5 | I7: ='Data Sheet'!I25 -> 158.99 | ... K7: ='Data Sheet'!K25 -> 160.23
A8: Depreciation | B8: ='Data Sheet'!B26 -> 342.25 | C8: ='Data Sheet'!C26 -> 335.67 | D8: ='Data Sheet'!D26 -> 370.15 | E8: ='Data Sheet'!E26 -> 370.38 | F8: ='Data Sheet'!F26 -> 391.02 | G8: ='Data Sheet'!G26 -> 403.01 | H8: ='Data Sheet'!H26 -> 428.91 | I8: ='Data Sheet'!I26 -> 567.75 | ... K8: ='Data Sheet'!K26 -> 699.23
A9: Interest | B9: ='Data Sheet'!B27 -> 91.9 | C9: ='Data Sheet'!C27 -> 111.95 | D9: ='Data Sheet'!D27 -> 129.12 | E9: ='Data Sheet'!E27 -> 164.18 | F9: ='Data Sheet'!F27 -> 201.68 | G9: ='Data Sheet'!G27 -> 154.57 | H9: ='Data Sheet'!H27 -> 119.29 | I9: ='Data Sheet'!I27 -> 145.49 | ... K9: ='Data Sheet'!K27 -> 158.31
A10: Profit before tax | B10: ='Data Sheet'!B28 -> 1839.3 | C10: ='Data Sheet'!C28 -> 2428.95 | D10: ='Data Sheet'!D28 -> 2673.49 | E10: ='Data Sheet'!E28 -> 2812.79 | F10: ='Data Sheet'!F28 -> 2857.32 | G10: ='Data Sheet'!G28 -> 3255.97 | H10: ='Data Sheet'!H28 -> 4038.29 | I10: ='Data Sheet'!I28 -> 5288.87 | ... K10: ='Data Sheet'!K28 -> 4609.65
A11: Tax | B11: ='Data Sheet'!B29 -> 614.11 | C11: ='Data Sheet'!C29 -> 822.02 | D11: ='Data Sheet'!D29 -> 705.05 | E11: ='Data Sheet'!E29 -> 730.36 | F11: ='Data Sheet'!F29 -> 738.91 | G11: ='Data Sheet'!G29 -> 865.45 | H11: ='Data Sheet'!H29 -> 1039.62 | I11: ='Data Sheet'!I29 -> 1356.03 | ... K11: ='Data Sheet'!K29 -> 1065.05
A12: Net profit | B12: ='Data Sheet'!B30 -> 1225.19 | C12: ='Data Sheet'!C30 -> 1606.93 | D12: ='Data Sheet'!D30 -> 1968.44 | E12: ='Data Sheet'!E30 -> 2082.43 | F12: ='Data Sheet'!F30 -> 2118.41 | G12: ='Data Sheet'!G30 -> 2390.52 | H12: ='Data Sheet'!H30 -> 2998.67 | I12: ='Data Sheet'!I30 -> 3932.84 | ... K12: ='Data Sheet'!K30 -> 3544.6
A13: EPS | B13: =IF('Data Sheet'!B93>0,B12/'Data Sheet'!B93,0) -> 6.3547199 | C13: =IF('Data Sheet'!C93>0,C12/'Data Sheet'!C93,0) -> 8.3346992 | D13: =IF('Data Sheet'!D93>0,D12/'Data Sheet'!D93,0) -> 10.209751 | E13: =IF('Data Sheet'!E93>0,E12/'Data Sheet'!E93,0) -> 10.800985 | F13: =IF('Data Sheet'!F93>0,F12/'Data Sheet'!F93,0) -> 10.987604 | G13: =IF('Data Sheet'!G93>0,G12/'Data Sheet'!G93,0) -> 12.398963 | H13: =IF('Data Sheet'!H93>0,H12/'Data Sheet'!H93,0) -> 15.553268 | I13: =IF('Data Sheet'!I93>0,I12/'Data Sheet'!I93,0) -> 20.395374 | ... K13: =IF('Data Sheet'!K93>0,K12/'Data Sheet'!K93,0) -> 18.381995
A14: Price to earning | B14: =IF(B15>0,B15/B13,"") -> 61.930345 | C14: =IF(C15>0,C15/C13,"") -> 66.497901 | D14: =IF(D15>0,D15/D13,"") -> 72.40823 | E14: =IF(E15>0,E15/E13,"") -> 85.132047 | F14: =IF(F15>0,F15/F13,"") -> 89.672874 | G14: =IF(G15>0,G15/G13,"") -> 79.063066 | H14: =IF(H15>0,H15/H13,"") -> 85.449568 | I14: =IF(I15>0,I15/I13,"") -> 64.288107 | ... K14: =IF(K15>0,K15/K13,"") -> 63.910366
A15: Price | B15: ='Data Sheet'!B90 -> 393.55 | C15: ='Data Sheet'!C90 -> 554.24 | D15: ='Data Sheet'!D90 -> 739.27 | E15: ='Data Sheet'!E90 -> 919.51 | F15: ='Data Sheet'!F90 -> 985.29 | G15: ='Data Sheet'!G90 -> 980.3 | H15: ='Data Sheet'!H90 -> 1329.02 | I15: ='Data Sheet'!I90 -> 1311.18 | ... K15: ='Data Sheet'!K90 -> 1174.8
A17: RATIOS:
A18: Dividend Payout | B18: =IF('Data Sheet'!B30>0, 'Data Sheet'!B31/'Data Sheet'!B30, 0) -> 0.67680115 | C18: =IF('Data Sheet'!C30>0, 'Data Sheet'!C31/'Data Sheet'!C30, 0) -> 0.69003006 | D18: =IF('Data Sheet'!D30>0, 'Data Sheet'!D31/'Data Sheet'!D30, 0) -> 1.6752149 | E18: =IF('Data Sheet'!E30>0, 'Data Sheet'!E31/'Data Sheet'!E30, 0) -> 0.92603353 | F18: =IF('Data Sheet'!F30>0, 'Data Sheet'!F31/'Data Sheet'!F30, 0) -> 0.91030537 | G18: =IF('Data Sheet'!G30>0, 'Data Sheet'!G31/'Data Sheet'!G30, 0) -> 0.88735505 | H18: =IF('Data Sheet'!H30>0, 'Data Sheet'!H31/'Data Sheet'!H30, 0) -> 0.5594847 | I18: =IF('Data Sheet'!I30>0, 'Data Sheet'!I31/'Data Sheet'!I30, 0) -> 0.78943461 | ... K18: =IF('Data Sheet'!K30>0, 'Data Sheet'!K31/'Data Sheet'!K30, 0) -> 0.65281273
A19: OPM | B19: =IF(B6>0,B6/B4,0) -> 0.20945193 | C19: =IF(C6>0,C6/C4,0) -> 0.23180902 | D19: =IF(D6>0,D6/D4,0) -> 0.23655135 | E19: =IF(E6>0,E6/E4,0) -> 0.2398122 | F19: =IF(F6>0,F6/F4,0) -> 0.24167282 | G19: =IF(G6>0,G6/G4,0) -> 0.21934656 | H19: =IF(H6>0,H6/H4,0) -> 0.23376137 | I19: =IF(I6>0,I6/I4,0) -> 0.23953211 | ... K19: =IF(K6>0,K6/K4,0) -> 0.22919679

Sheet Balance Sheet
A1: ='Profit & Loss'!A1 -> NESTLE INDIA LTD | E1: =UPDATE | J1: SCREENER.IN
A3: Narration | B3: ='Data Sheet'!B56 -> 43100 | C3: ='Data Sheet'!C56 -> 43465 | D3: ='Data Sheet'!D56 -> 43830 | E3: ='Data Sheet'!E56 -> 44196 | F3: ='Data Sheet'!F56 -> 44561 | G3: ='Data Sheet'!G56 -> 44926 | H3: ='Data Sheet'!H56 -> 45291 | I3: ='Data Sheet'!I56 -> 45382 | ... K3: ='Data Sheet'!K56 -> 46112
A4: Equity Share Capital | B4: ='Data Sheet'!B57 -> 96.42 | C4: ='Data Sheet'!C57 -> 96.42 | D4: ='Data Sheet'!D57 -> 96.42 | E4: ='Data Sheet'!E57 -> 96.42 | F4: ='Data Sheet'!F57 -> 96.42 | G4: ='Data Sheet'!G57 -> 96.42 | H4: ='Data Sheet'!H57 -> 96.42 | I4: ='Data Sheet'!I57 -> 96.42 | ... K4: ='Data Sheet'!K57 -> 192.83
A5: Reserves | B5: ='Data Sheet'!B58 -> 3324.17 | C5: ='Data Sheet'!C58 -> 3577.32 | D5: ='Data Sheet'!D58 -> 1822.45 | E5: ='Data Sheet'!E58 -> 1922.92 | F5: ='Data Sheet'!F58 -> 1849.96 | G5: ='Data Sheet'!G58 -> 2362.75 | H5: ='Data Sheet'!H58 -> 2362.75 | I5: ='Data Sheet'!I58 -> 3244.47 | ... K5: ='Data Sheet'!K58 -> 5116.41
A6: Borrowings | B6: ='Data Sheet'!B59 -> 35.14 | C6: ='Data Sheet'!C59 -> 35.14 | D6: ='Data Sheet'!D59 -> 188.94 | E6: ='Data Sheet'!E59 -> 147.49 | F6: ='Data Sheet'!F59 -> 266.46 | G6: ='Data Sheet'!G59 -> 270.52 | H6: ='Data Sheet'!H59 -> 270.52 | I6: ='Data Sheet'!I59 -> 344.53 | ... K6: ='Data Sheet'!K59 -> 444.16
A7: Other Liabilities | B7: ='Data Sheet'!B60 -> 3906.86 | C7: ='Data Sheet'!C60 -> 4379.2 | D7: ='Data Sheet'!D60 -> 5065.13 | E7: ='Data Sheet'!E60 -> 5732.9 | F7: ='Data Sheet'!F60 -> 6021.29 | G7: ='Data Sheet'!G60 -> 6249.05 | H7: ='Data Sheet'!H60 -> 6249.05 | I7: ='Data Sheet'!I60 -> 6837.64 | ... K7: ='Data Sheet'!K60 -> 7603.77
A8: Total | B8: ='Data Sheet'!B61 -> 7362.59 | C8: ='Data Sheet'!C61 -> 8088.08 | D8: ='Data Sheet'!D61 -> 7172.94 | E8: ='Data Sheet'!E61 -> 7899.73 | F8: ='Data Sheet'!F61 -> 8234.13 | G8: ='Data Sheet'!G61 -> 8978.74 | H8: ='Data Sheet'!H61 -> 8978.74 | I8: ='Data Sheet'!I61 -> 10523.06 | ... K8: ='Data Sheet'!K61 -> 13357.17
A10: Net Block | B10: ='Data Sheet'!B62 -> 2616.18 | C10: ='Data Sheet'!C62 -> 2400.62 | D10: ='Data Sheet'!D62 -> 2341.45 | E10: ='Data Sheet'!E62 -> 2179.41 | F10: ='Data Sheet'!F62 -> 2994.67 | G10: ='Data Sheet'!G62 -> 3043.7 | H10: ='Data Sheet'!H62 -> 3043.7 | I10: ='Data Sheet'!I62 -> 3460.25 | ... K10: ='Data Sheet'!K62 -> 6290.42
A11: Capital Work in Progress | B11: ='Data Sheet'!B63 -> 94.16 | C11: ='Data Sheet'!C63 -> 105.2 | D11: ='Data Sheet'!D63 -> 143.3 | E11: ='Data Sheet'!E63 -> 638.58 | F11: ='Data Sheet'!F63 -> 246.23 | G11: ='Data Sheet'!G63 -> 358.36 | H11: ='Data Sheet'!H63 -> 358.36 | I11: ='Data Sheet'!I63 -> 1741.71 | ... K11: ='Data Sheet'!K63 -> 506.98
A12: Investments | B12: ='Data Sheet'!B64 -> 1978.87 | C12: ='Data Sheet'!C64 -> 2658.49 | D12: ='Data Sheet'!D64 -> 1751.05 | E12: ='Data Sheet'!E64 -> 1463.77 | F12: ='Data Sheet'!F64 -> 773.98 | G12: ='Data Sheet'!G64 -> 777.54 | H12: ='Data Sheet'!H64 -> 777.54 | I12: ='Data Sheet'!I64 -> 463.87 | ... K12: ='Data Sheet'!K64 -> 705.6
A13: Other Assets | B13: ='Data Sheet'!B65 -> 2673.38 | C13: ='Data Sheet'!C65 -> 2923.77 | D13: ='Data Sheet'!D65 -> 2937.14 | E13: ='Data Sheet'!E65 -> 3617.97 | F13: ='Data Sheet'!F65 -> 4219.25 | G13: ='Data Sheet'!G65 -> 4799.14 | H13: ='Data Sheet'!H65 -> 4799.14 | I13: ='Data Sheet'!I65 -> 4857.23 | ... K13: ='Data Sheet'!K65 -> 5854.17
A14: Total | B14: ='Data Sheet'!B66 -> 7362.59 | C14: ='Data Sheet'!C66 -> 8088.08 | D14: ='Data Sheet'!D66 -> 7172.94 | E14: ='Data Sheet'!E66 -> 7899.73 | F14: ='Data Sheet'!F66 -> 8234.13 | G14: ='Data Sheet'!G66 -> 8978.74 | H14: ='Data Sheet'!H66 -> 8978.74 | I14: ='Data Sheet'!I66 -> 10523.06 | ... K14: ='Data Sheet'!K66 -> 13357.17
A16: Working Capital | B16: =B13-B7 -> -1233.48 | C16: =C13-C7 -> -1455.43 | D16: =D13-D7 -> -2127.99 | E16: =E13-E7 -> -2114.93 | F16: =F13-F7 -> -1802.04 | G16: =G13-G7 -> -1449.91 | H16: =H13-H7 -> -1449.91 | I16: =I13-I7 -> -1980.41 | ... K16: =K13-K7 -> -1749.6
A17: Debtors | B17: ='Data Sheet'!B67 -> 88.97 | C17: ='Data Sheet'!C67 -> 124.59 | D17: ='Data Sheet'!D67 -> 124.33 | E17: ='Data Sheet'!E67 -> 164.93 | F17: ='Data Sheet'!F67 -> 165.97 | G17: ='Data Sheet'!G67 -> 191.89 | H17: ='Data Sheet'!H67 -> 191.89 | I17: ='Data Sheet'!I67 -> 300.46 | ... K17: ='Data Sheet'!K67 -> 329.47
A18: Inventory | B18: ='Data Sheet'!B68 -> 902.47 | C18: ='Data Sheet'!C68 -> 965.55 | D18: ='Data Sheet'!D68 -> 1283.07 | E18: ='Data Sheet'!E68 -> 1416.48 | F18: ='Data Sheet'!F68 -> 1592.65 | G18: ='Data Sheet'!G68 -> 1928.77 | H18: ='Data Sheet'!H68 -> 1928.77 | I18: ='Data Sheet'!I68 -> 2089.36 | ... K18: ='Data Sheet'!K68 -> 2569.22
A20: Debtor Days | B20: =IF('Profit & Loss'!B4>0,'Balance Sheet'!B17/('Profit & Loss'!B4/365),0) -> 3.2442905 | C20: =IF('Profit & Loss'!C4>0,'Balance Sheet'!C17/('Profit & Loss'!C4/365),0) -> 4.0271221 | D20: =IF('Profit & Loss'!D4>0,'Balance Sheet'!D17/('Profit & Loss'!D4/365),0) -> 3.6689156 | E20: =IF('Profit & Loss'!E4>0,'Balance Sheet'!E17/('Profit & Loss'!E4/365),0) -> 4.509312 | F20: =IF('Profit & Loss'!F4>0,'Balance Sheet'!F17/('Profit & Loss'!F4/365),0) -> 4.1096761 | G20: =IF('Profit & Loss'!G4>0,'Balance Sheet'!G17/('Profit & Loss'!G4/365),0) -> 4.1451155 | H20: =IF('Profit & Loss'!H4>0,'Balance Sheet'!H17/('Profit & Loss'!H4/365),0) -> 3.6619655 | I20: =IF('Profit & Loss'!I4>0,'Balance Sheet'!I17/('Profit & Loss'!I4/365),0) -> 4.4957118 | ... K20: =IF('Profit & Loss'!K4>0,'Balance Sheet'!K17/('Profit & Loss'!K4/365),0) -> 5.1936354
A21: Inventory Turnover | B21: =IF('Balance Sheet'!B18>0,'Profit & Loss'!B4/'Balance Sheet'!B18,0) -> 11.091338 | C21: =IF('Balance Sheet'!C18>0,'Profit & Loss'!C4/'Balance Sheet'!C18,0) -> 11.695169 | D21: =IF('Balance Sheet'!D18>0,'Profit & Loss'!D4/'Balance Sheet'!D18,0) -> 9.640082 | E21: =IF('Balance Sheet'!E18>0,'Profit & Loss'!E4/'Balance Sheet'!E18,0) -> 9.4247924 | F21: =IF('Balance Sheet'!F18>0,'Profit & Loss'!F4/'Balance Sheet'!F18,0) -> 9.2553857 | G21: =IF('Balance Sheet'!G18>0,'Profit & Loss'!G4/'Balance Sheet'!G18,0) -> 8.7604847 | H21: =IF('Balance Sheet'!H18>0,'Profit & Loss'!H4/'Balance Sheet'!H18,0) -> 9.9163197 | I21: =IF('Balance Sheet'!I18>0,'Profit & Loss'!I4/'Balance Sheet'!I18,0) -> 11.675293 | ... K21: =IF('Balance Sheet'!K18>0,'Profit & Loss'!K4/'Balance Sheet'!K18,0) -> 9.0123072
A23: Return on Equity | B23: =IF(SUM('Balance Sheet'!B4:B5)>0,'Profit & Loss'!B12/SUM('Balance Sheet'!B4:B5),"") -> 0.3581809 | C23: =IF(SUM('Balance Sheet'!C4:C5)>0,'Profit & Loss'!C12/SUM('Balance Sheet'!C4:C5),"") -> 0.43740983 | D23: =IF(SUM('Balance Sheet'!D4:D5)>0,'Profit & Loss'!D12/SUM('Balance Sheet'!D4:D5),"") -> 1.0258329 | E23: =IF(SUM('Balance Sheet'!E4:E5)>0,'Profit & Loss'!E12/SUM('Balance Sheet'!E4:E5),"") -> 1.0312429 | F23: =IF(SUM('Balance Sheet'!F4:F5)>0,'Profit & Loss'!F12/SUM('Balance Sheet'!F4:F5),"") -> 1.0883846 | G23: =IF(SUM('Balance Sheet'!G4:G5)>0,'Profit & Loss'!G12/SUM('Balance Sheet'!G4:G5),"") -> 0.97208408 | H23: =IF(SUM('Balance Sheet'!H4:H5)>0,'Profit & Loss'!H12/SUM('Balance Sheet'!H4:H5),"") -> 1.219383 | I23: =IF(SUM('Balance Sheet'!I4:I5)>0,'Profit & Loss'!I12/SUM('Balance Sheet'!I4:I5),"") -> 1.1771833 | ... K23: =IF(SUM('Balance Sheet'!K4:K5)>0,'Profit & Loss'!K12/SUM('Balance Sheet'!K4:K5),"") -> 0.66762851
A24: Return on Capital Emp | C24: =IF((B4+B5+B6+C4+C5+C6)>0,('Profit & Loss'!C10+'Profit & Loss'!C9)*2/(B4+B5+B6+C4+C5+C6),"") -> 0.70929192 | D24: =IF((C4+C5+C6+D4+D5+D6)>0,('Profit & Loss'!D10+'Profit & Loss'!D9)*2/(C4+C5+C6+D4+D5+D6),"") -> 0.96364427 | E24: =IF((D4+D5+D6+E4+E5+E6)>0,('Profit & Loss'!E10+'Profit & Loss'!E9)*2/(D4+D5+D6+E4+E5+E6),"") -> 1.3928518 | F24: =IF((E4+E5+E6+F4+F5+F6)>0,('Profit & Loss'!F10+'Profit & Loss'!F9)*2/(E4+E5+E6+F4+F5+F6),"") -> 1.3969089 | G24: =IF((F4+F5+F6+G4+G5+G6)>0,('Profit & Loss'!G10+'Profit & Loss'!G9)*2/(F4+F5+F6+G4+G5+G6),"") -> 1.3800786 | H24: =IF((G4+G5+G6+H4+H5+H6)>0,('Profit & Loss'!H10+'Profit & Loss'!H9)*2/(G4+G5+G6+H4+H5+H6),"") -> 1.523096 | I24: =IF((H4+H5+H6+I4+I5+I6)>0,('Profit & Loss'!I10+'Profit & Loss'!I9)*2/(H4+H5+H6+I4+I5+I6),"") -> 1.6942375 | J24: =IF((I4+I5+I6+J4+J5+J6)>0,('Profit & Loss'!J10+'Profit & Loss'!J9)*2/(I4+I5+I6+J4+J5+J6),"") -> 1.0220215 | K24: =IF((J4+J5+J6+K4+K5+K6)>0,('Profit & Loss'!K10+'Profit & Loss'!K9)*2/(J4+J5+J6+K4+K5+K6),"") -> 0.86396434

Sheet Cash Flow Data
C1: 43435 | D1: 43800 | E1: 44166 | F1: 44531 | G1: 44896 | H1: 45261 | I1: 45352 | J1: 45717 | K1: 46082
B2: Cash from Operating Activity - | C2: 2052 | D2: 2295 | E2: 2454 | F2: 2236 | G2: 2737 | H2: 3392 | I2: 4175 | J2: 2935 | K2: 5048
B3: Profit from operations | C3: 2521 | D3: 2805 | E3: 3061 | F3: 3136 | G3: 3609 | H3: 4388 | I3: 5722 | J3: 4672 | K3: 5326
B4: Receivables | C4: -36 | D4: 0 | E4: -42 | F4: -2 | G4: -28 | H4: -11 | I4: -109 | J4: -70 | K4: 34
B5: Inventory | C5: -63 | D5: -318 | E5: -133 | F5: -169 | G5: -336 | H5: 56 | I5: -161 | J5: -767 | K5: 281
B6: Payables | C6: 257 | D6: 253 | E6: 23 | F6: 217 | G6: 178 | H6: 68 | I6: 310 | J6: 134 | K6: 588
B7: Loans Advances | C7: 0 | D7: 0 | E7: 0 | F7: -40 | G7: -30 | H7: -30 | I7: -21 | J7: -199 | K7: -73
B8: Operating borrowings | C8: 0 | D8: 0 | E8: 0 | F8: 0 | G8: 0 | H8: 0 | I8: 0 | J8: 0 | K8: 0
B9: Other WC items | C9: 255 | D9: 227 | E9: 249 | F9: -179 | G9: 185 | H9: -19 | I9: -268 | J9: 155 | K9: -37
B10: Working capital changes | C10: 413 | D10: 163 | E10: 97 | F10: -172 | G10: -30 | H10: 63 | I10: -249 | J10: -747 | K10: 793
B11: Direct taxes | C11: -881 | D11: -673 | E11: -703 | F11: -729 | G11: -841 | H11: -1059 | I11: -1299 | J11: -990 | K11: -1071
B12: Cash from Investing Activity - | C12: -52 | D12: 83 | E12: -321 | F12: -1920 | G12: -392 | H12: -927 | I12: -1237 | J12: -1811 | K12: -624
B13: Fixed assets purchased | C13: -166 | D13: -155 | E13: -478 | F13: -735 | G13: -550 | H13: -1371 | I13: -1883 | J13: -2009 | K13: -830
... B31: CFO/OP | C31: 1.12 | D31: 1.01 | E31: 0.99 | F31: 0.83 | G31: 0.97 | H31: 1 | I31: 0.94 | J31: 0.82 | K31: 1.15
